Workbook

Sheet DATA
B2: YAYASAN AL – IHSAN AL ISLAMI
B3: MTs. AL IHSAN TANAH GROGOT
B4: NPSN : 30410000 NSM : 12.12.64.01.0002
B5: Alamat : Jl. Senaken Ds. Senaken RT. IV Tanah Grogot Kab. Paser - Kalimantan Timur 76211
B6: Telp. 0543-5236320 e-mail: mtsalihsan__senaken@yahoo.com
C13: DATA UMUM | U13: JANUARI
U14: FEBRUARI
C15: TAHUN PELAJARAN | E15: 2026/2027 | I15: Kepala Madrasah : | K15: Ahmad Syafi'i Badar,S.Pd.I | N15: Pengawas Madrasah : | P15: Drs.H.Hadi Suhaidy. | U15: MARET
U16: APRIL
C17: WAKTU LAPORAN | E17: JULI | G17: 2026 | I17: NIP : | K17: - | N17: NIP : | P17: 196707121996031003 | U17: MEI
U18: JUNI
C19: IDENTITAS GURU | J19: IDENTITAS MADRASAH | U19: JULI
C20: Nama Guru | E20: Nurlailatul Hasanah, S.Ag | L20: Nama Madrasah | N20: MTs. AL IHSAN TANAH GROGOT | U20: AGUSTUS
U21: SEPTEMBER
C22: NIP | E22: 197311272005012002 | L22: Alamat Madrasah | N22: Jl. Cendrawasih RT. 04 Desa Senaken Tanah Grogot | U22: OKTOBER
U23: NOVEMBER
C24: No Sertifikasi | E24: 2111423801163 | L24: Jumlah Ruang Kelas | N24: 6 (Enam) | U24: DESEMBER
C26: Pangkat/Gol Ruang | E26: Guru madya pembina tingkat I, golongan IV/b | L26: Status Madrasah | N26: Terakreditasi A
C28: Pendidikan | E28: S.1 Tarbiyah | L28: Internet | N28: Ada
C30: Status Guru | E30: Sejarah Kebudayaan Islam (SKI) dan Akidah Akhlak | U30: Guru pertama penata muda, golongan III/a | Y30: VII A | AA30: Guru pertama | AB30: Pangkat penata muda, golongan III/a
U31: Guru pertama penata muda tingkat I, golongan III/b | Y31: VII B | AA31: Guru pertama | AB31: Pangkat penata muda tingkat I, golongan III/b
C32: ="DATA JUMLAH SISWA/PESERTA EKSTRAKURIKULER BULAN "&E17&" "&G17 -> DATA JUMLAH SISWA/PESERTA EKSTRAKURIKULER BULAN JULI 2026 | U32: Guru muda penata, golongan III/c | Y32: VII C | AA32: Guru muda | AB32: Pangkat penata, golongan III/c
U33: Guru muda penata tingkat I, golongan III/d | Y33: VII D | AA33: Guru muda | AB33: Pangkat penata tingkat I, golongan III/d
D34: TINGKAT 7 | H34: TINGKAT 8 | M34: TINGKAT 9 | U34: Guru madya pembina, golongan IV/a | Y34: VIII A | AA34: Guru madya | AB34: Pangkat pembina, golongan IV/a
D35: VII A | E35: VII B | H35: VIII A | I35: VIII B | M35: IX A | N35: IX B | O35: IX C | U35: Guru madya pembina tingkat I, golongan IV/b | Y35: VIII B | AA35: Guru madya | AB35: Pangkat pembina tingkat I, golongan IV/b
C36: L | D36: 24 | E36: 0 | H36: 22 | I36: 12 | M36: 23 | N36: 0 | U36: Guru madya pembina utama muda, golongan IV/c | Y36: VIII C | AA36: Guru madya | AB36: Pangkat pembina utama muda, golongan IV/c
C37: P | D37: 0 | E37: 20 | H37: 0 | I37: 11 | M37: 0 | N37: 31 | U37: Guru utama pembina utama madya, golongan IV/d | Y37: VIII D | AA37: Guru utama | AB37: Pangkat pembina utama madya, golongan IV/d
U38: Guru utama pembina utama, golongan IV/e | Y38: VIII E | AA38: Guru utama | AB38: Pangkat pembina utama, golongan IV/e
J39: EKSTRAKURIKULER | Y39: IX A
J40: OP | K40: AH | Y40: IX B
Y41: IX C
Y42: IX D
Y43: IX E
C44: ="JUMLAH HARI EFEKTIF/KEGIATAN EKSTRAKURIKULER BULAN "&E17&" "&G17 -> JUMLAH HARI EFEKTIF/KEGIATAN EKSTRAKURIKULER BULAN JULI 2026
G46: SENIN | H46: SELASA | I46: RABU | J46: KAMIS | K46: JUMAT | L46: SABTU | M46: =IF(J40="","",J40) -> OP | N46: =IF(K40="","",K40) -> AH
G47: 3 | H47: 3 | I47: 3 | J47: 3 | K47: 3 | L47: 2

Sheet DATA 1
B2: YAYASAN AL – IHSAN AL ISLAMI
B3: MTs. AL IHSAN TANAH GROGOT
B4: NPSN : 30410000 NSM : 12.12.64.01.0002
B5: Alamat : Jl. Senaken Ds. Senaken RT. IV Tanah Grogot Kab. Paser - Kalimantan Timur 76211
B6: Telp. 0543-5236320 e-mail: mtsalihsan__senaken@yahoo.com
C11: PETUNJUK PENGGUNAAN DAPAT DIBACA DI SINI
C13: DATA UMUM | U13: JANUARI
U14: FEBRUARI
C15: TAHUN PELAJARAN | E15: 2022/2023 | H15: Kepala Madrasah : | J15: Ahmad Syafi'i Badar,S.Pd.I | L15: Pengawas Madrasah : | N15: H.Najimuddin,S.Ag. | U15: MARET
U16: APRIL
C17: WAKTU LAPORAN | E17: JULI | G17: 2022 | H17: NIP : | J17: - | L17: NIP : | N17: 196411191994031003 | U17: MEI
U18: JUNI
C19: IDENTITAS GURU | J19: IDENTITAS MADRASAH | U19: JULI
C20: Nama Guru | E20: Nurlailatul Hasanah, S.Ag | J20: Nama Madrasah | L20: MTs. AL IHSAN TANAH GROGOT | U20: AGUSTUS
U21: SEPTEMBER
C22: NIP | E22: 197311272005012002 | J22: Alamat Madrasah | L22: Jl. Cendrawasih RT. 04 Desa Senaken Tanah Grogot | U22: OKTOBER
U23: NOVEMBER
C24: No Sertifikasi | E24: 2111423801163 | J24: Jumlah Ruang Kelas | L24: 12 (Dua Belas) | U24: DESEMBER
C26: Pangkat/Gol Ruang | E26: Pembina (IV/a) | J26: Status Madrasah | L26: Terakreditasi A
C28: Pendidikan | E28: S.1 Tarbiyah | J28: Internet | L28: Ada
C30: Status Guru | E30: Sejarah Kebudayaan Islam dan Akidah Akhlak | U30: Penata Muda (III/a) | Y30: VII A
U31: Penata Muda Tingkat I (III/b) | Y31: VII B
C32: ="DATA JUMLAH SISWA/PESERTA EKSTRAKURIKULER BULAN "&E17&" "&G17 -> DATA JUMLAH SISWA/PESERTA EKSTRAKURIKULER BULAN JULI 2022 | U32: Penata Tingkat I (III/d) | Y32: VIII A
U33: Pembina (IV/a) | Y33: VIII B
D34: TINGKAT 7 | I34: TINGKAT 8 | M34: TINGKAT 9 | U34: Pembina Tingkat I (IV/b) | Y34: VIII C
D35: VII A | E35: VII B | F35: VII C | G35: VII D | H35: VII E | I35: VIII A | J35: VIII B | K35: VIII C | L35: VIII D | M35: IX A | N35: IX B | O35: IX C | U35: Pembina Utama Muda (IV/c) | Y35: IX A
C36: L | U36: Pembina Utama Madya (IV/d) | Y36: IX B
C37: P | U37: Pembina Utama (IV/e) | Y37: IX C
I39: EKSTRAKURIKULER
I40: apa ya | J40: pramua
C44: ="JUMLAH HARI EFEKTIF/KEGIATAN EKSTRAKURIKULER BULAN "&E17&" "&G17 -> JUMLAH HARI EFEKTIF/KEGIATAN EKSTRAKURIKULER BULAN JULI 2022
F46: SENIN | G46: SELASA | H46: RABU | I46: KAMIS | J46: JUMAT | K46: SABTU | L46: =IF(I40="","",I40) -> apa ya | M46: =IF(J40="","",J40) -> pramua
F47: 3 | G47: 3 | H47: 3 | I47: 4 | J47: 4 | K47: 4

Sheet proses
B21: =JURNAL_LKH!B21 -> Rabu | C21: =B21&JURNAL_LKH!E21&JURNAL_LKH!F21 -> Rabu07.30-10.00
B22: =IF(JURNAL_LKH!B22="",B21,JURNAL_LKH!B22) -> Rabu | C22: =B22&JURNAL_LKH!E22&JURNAL_LKH!F22 -> Rabu10.00-12.00
B23: =IF(JURNAL_LKH!B23="",B22,JURNAL_LKH!B23) -> Rabu | C23: =B23&JURNAL_LKH!E23&JURNAL_LKH!F23 -> Rabu12.00-13.00
B24: =IF(JURNAL_LKH!B24="",B23,JURNAL_LKH!B24) -> Rabu | C24: =B24&JURNAL_LKH!E24&JURNAL_LKH!F24 -> Rabu13.00-15.00
B25: =IF(JURNAL_LKH!B25="",B24,JURNAL_LKH!B25) -> Kamis | C25: =B25&JURNAL_LKH!E25&JURNAL_LKH!F25 -> Kamis07.20-12.00
B26: =IF(JURNAL_LKH!B26="",B25,JURNAL_LKH!B26) -> Kamis | C26: =B26&JURNAL_LKH!E26&JURNAL_LKH!F26 -> Kamis12.00-13.00
B27: =IF(JURNAL_LKH!B27="",B26,JURNAL_LKH!B27) -> Kamis | C27: =B27&JURNAL_LKH!E27&JURNAL_LKH!F27 -> Kamis13.00-15.00
B28: =IF(JURNAL_LKH!B28="",B27,JURNAL_LKH!B28) -> Jumat | C28: =B28&JURNAL_LKH!E28&JURNAL_LKH!F28 -> Jumat07.30-12.00
B29: =IF(JURNAL_LKH!B29="",B28,JURNAL_LKH!B29) -> Sabtu | C29: =B29&JURNAL_LKH!E29&JURNAL_LKH!F29 -> Sabtu07.30-10.00
B30: =IF(JURNAL_LKH!B30="",B29,JURNAL_LKH!B30) -> Sabtu | C30: =B30&JURNAL_LKH!E30&JURNAL_LKH!F30 -> Sabtu10.00-12.00
B31: =IF(JURNAL_LKH!B31="",B30,JURNAL_LKH!B31) -> Sabtu | C31: =B31&JURNAL_LKH!E31&JURNAL_LKH!F31 -> Sabtu12.00-13.00
B32: =IF(JURNAL_LKH!B32="",B31,JURNAL_LKH!B32) -> Sabtu | C32: =B32&JURNAL_LKH!E32&JURNAL_LKH!F32 -> Sabtu13.00-15.00
B33: =IF(JURNAL_LKH!B33="",B32,JURNAL_LKH!B33) -> Senin | C33: =B33&JURNAL_LKH!E33&JURNAL_LKH!F33 -> Senin07.15-10.00
... B188: =IF(JURNAL_LKH!B188="",B187,JURNAL_LKH!B188) -> Sabtu | C188: =B188&JURNAL_LKH!E188&JURNAL_LKH!F188 -> Sabtu

Sheet JURNAL_LKH
A1: YAYASAN AL – IHSAN AL ISLAMI
A2: MTs. AL IHSAN TANAH GROGOT
A3: NPSN : 30410000 NSM : 12.12.64.01.0002
A4: Alamat : Jl. Senaken Ds. Senaken RT. IV Tanah Grogot Kab. Paser - Kalimantan Timur 76211
A5: Telp. 0543-5236320 e-mail: mtsalihsan__senaken@yahoo.com
A8: JURNAL MENGAJAR DAN LAPORAN KINERJA HARIAN
A9: ="BULAN : "&DATA!E17&" "&DATA!G17 -> BULAN : JULI 2026
A10: IDENTITAS GURU | I10: IDENTITAS MADRASAH
A11: ="Nama Guru : "&DATA!E20 -> Nama Guru : Nurlailatul Hasanah, S.Ag | I11: =" Nama Madrasah : "&DATA!N20 -> Nama Madrasah : MTs. AL IHSAN TANAH GROGOT
A12: ="NIP : "&DATA!E22 -> NIP : 197311272005012002 | I12: =" Alamat Madrasah : "&DATA!N22 -> Alamat Madrasah : Jl. Cendrawasih RT. 04 Desa Senaken Tanah Grogot
A13: ="No Sertifikasi : "&DATA!E24 -> No Sertifikasi : 2111423801163 | I13: =" Jumlah Ruang Kelas : "&DATA!N24 -> Jumlah Ruang Kelas : 6 (Enam)
A14: ="Pangkat/Gol Ruang : "&DATA!E26 -> Pangkat/Gol Ruang : Guru madya pembina tingkat I, golongan IV/b | I14: =" Status Madrasah : "&DATA!N26 -> Status Madrasah : Terakreditasi A
A15: ="Pendidikan : "&DATA!E28 -> Pendidikan : S.1 Tarbiyah | I15: =" Internet : "&DATA!N28 -> Internet : Ada
A16: ="Status Guru : "&DATA!E30 -> Status Guru : Sejarah Kebudayaan Islam (SKI) dan Akidah Akhlak
A19: No | B19: Hari/Tanggal | E19: Jam ke- | F19: Kelas/Ekskul | G19: Mata Pelajaran | H19: No KI/KD | I19: Kegiatan/Materi | J19: Hasil | K19: Vol | L19: Absensi | O19: Ket
B20: Hari | C20: Tgl Bulan Tahun | L20: S | M20: I | N20: A
A21: 1. | B21: =IF(C21="","",TEXT(C21&D21,"dddd")) -> Rabu | C21: 1 | D21: =IF(C21="","",PROPER(DATA!$E$17)&" "&DATA!$G$17) -> Juli 2026 | E21: 07.30-10.00 | I21: Membuat analisis hari efektif pembelajaran semester ganjil mapel SKI kls 7 TP 2026/2027 | J21: Terlaksana | K21: 1 Keg
A22: =IF(C22="","",COUNT($C$21:D22)&".") | B22: =IF(C22="","",TEXT(C22&D22,"dddd")) | D22: =IF(C22="","",PROPER(DATA!$E$17)&" "&DATA!$G$17) | E22: 10.00-12.00 | I22: Melanjutkan kegiatan membuat analisis hari efektif mapel SKI kls 8 TP 2026/2027 semester ganjil | J22: Terlaksana | K22: 1 Keg
A23: =IF(C23="","",COUNT($C$21:D23)&".") | B23: =IF(C23="","",TEXT(C23&D23,"dddd")) | D23: =IF(C23="","",PROPER(DATA!$E$17)&" "&DATA!$G$17) | E23: 12.00-13.00 | I23: Istirahat dan Shalat Dzuhur | J23: Terlaksana | K23: 1 Keg
A24: =IF(C24="","",COUNT($C$21:D24)&".") | B24: =IF(C24="","",TEXT(C24&D24,"dddd")) | D24: =IF(C24="","",PROPER(DATA!$E$17)&" "&DATA!$G$17) | E24: 13.00-15.00 | I24: Melanjutkan kegiatan membuat analisis hari efektif mapel SKI kls 9 TP 2026/2027 semester ganjil | J24: Terlaksana | K24: 1 Keg
A25: =IF(C25="","",COUNT($C$21:D25)&".") -> 2. | B25: =IF(C25="","",TEXT(C25&D25,"dddd")) -> Kamis | C25: 2 | D25: =IF(C25="","",PROPER(DATA!$E$17)&" "&DATA!$G$17) -> Juli 2026 | E25: 07.20-12.00 | I25: Menyiapkan bahan ajar untuk membuat Program Tahunan Mapel SKI kls 9 Semester Ganjil Mapel SKI TP 2026/2027 | J25: Terlaksana | K25: 1 Keg
A26: =IF(C26="","",COUNT($C$21:D26)&".") | B26: =IF(C26="","",TEXT(C26&D26,"dddd")) | D26: =IF(C26="","",PROPER(DATA!$E$17)&" "&DATA!$G$17) | E26: 12.00-13.00 | I26: Istirahat dan Shalat Dzuhur | J26: Terlaksana | K26: 1 Keg
A27: =IF(C27="","",COUNT($C$21:D27)&".") | B27: =IF(C27="","",TEXT(C27&D27,"dddd")) | D27: =IF(C27="","",PROPER(DATA!$E$17)&" "&DATA!$G$17) | E27: 13.00-15.00 | I27: Melanjutkan kegiatan membuat Program Tahunan Mapel SKI kls 9 | J27: Terlaksana | K27: 1 Keg
A28: =IF(C28="","",COUNT($C$21:D28)&".") -> 3. | B28: =IF(C28="","",TEXT(C28&D28,"dddd")) -> Jumat | C28: 3 | D28: =IF(C28="","",PROPER(DATA!$E$17)&" "&DATA!$G$17) -> Juli 2026 | E28: 07.30-12.00 | I28: Membuat program semester Mapel SKI kls 9 | J28: Terlaksana | K28: 1 Keg
A29: =IF(C29="","",COUNT($C$21:D29)&".") -> 4. | B29: =IF(C29="","",TEXT(C29&D29,"dddd")) -> Sabtu | C29: 4 | D29: =IF(C29="","",PROPER(DATA!$E$17)&" "&DATA!$G$17) -> Juli 2026 | E29: 07.30-10.00 | I29: Melanjutkan membuat program semester mapel SKI kls 9 | J29: Terlaksana | K29: 1 Keg
A30: =IF(C30="","",COUNT($C$21:D30)&".") | B30: =IF(C30="","",TEXT(C30&D30,"dddd")) | D30: =IF(C30="","",PROPER(DATA!$E$17)&" "&DATA!$G$17) | E30: 10.00-12.00 | I30: Menyiapkan bahan menyusun program pembelajaran semester mapel SKI kls 9 | J30: Terlaksana | K30: 1 Keg
A31: =IF(C31="","",COUNT($C$21:D31)&".") | B31: =IF(C31="","",TEXT(C31&D31,"dddd")) | D31: =IF(C31="","",PROPER(DATA!$E$17)&" "&DATA!$G$17) | E31: 12.00-13.00 | I31: Istirahat dan Shalat Dzuhur | J31: Terlaksana | K31: 1 Keg
A32: =IF(C32="","",COUNT($C$21:D32)&".") | B32: =IF(C32="","",TEXT(C32&D32,"dddd")) | D32: =IF(C32="","",PROPER(DATA!$E$17)&" "&DATA!$G$17) | E32: 13.00-15.00 | I32: Melanjutkan kegiatan membuat program pembelajaran semester ganjil mapel SKI kls 9 | J32: Terlaksana | K32: 1 Keg
A33: =IF(C33="","",COUNT($C$21:D33)&".") -> 5. | B33: =IF(C33="","",TEXT(C33&D33,"dddd")) -> Senin | C33: 6 | D33: =IF(C33="","",PROPER(DATA!$E$17)&" "&DATA!$G$17) -> Juli 2026 | E33: 07.15-10.00 | I33: Menyiapkan bahan ajar untuk memyusun program Tahunan mapel SKI kls 7 | J33: Terlaksana | K33: 1 Keg
A34: =IF(C34="","",COUNT($C$21:D34)&".") | B34: =IF(C34="","",TEXT(C34&D34,"dddd")) | D34: =IF(C34="","",PROPER(DATA!$E$17)&" "&DATA!$G$17) | E34: 10.00-12.00 | I34: Membuat Program Tahunan Mapel SKI kls 7 TP 2026/2027 semester ganjil | J34: Terlaksana | K34: 1 Keg
A35: =IF(C35="","",COUNT($C$21:D35)&".") | B35: =IF(C35="","",TEXT(C35&D35,"dddd")) | D35: =IF(C35="","",PROPER(DATA!$E$17)&" "&DATA!$G$17) | E35: 12.00-13.00 | I35: Istirahat dan Shalat Dzuhur | J35: Terlaksana | K35: 1 Keg
A36: =IF(C36="","",COUNT($C$21:D36)&".") | B36: =IF(C36="","",TEXT(C36&D36,"dddd")) | D36: =IF(C36="","",PROPER(DATA!$E$17)&" "&DATA!$G$17) | E36: 13.00-15.00 | I36: Melanjutkan membuat program semester mapel SKI kls 7 | J36: Terlaksana | K36: 1 Keg
A37: =IF(C37="","",COUNT($C$21:D37)&".") -> 6. | B37: =IF(C37="","",TEXT(C37&D37,"dddd")) -> Selasa | C37: 7 | D37: =IF(C37="","",PROPER(DATA!$E$17)&" "&DATA!$G$17) -> Juli 2026 | E37: 07.30-10.00 | I37: Merapikan dan menyusun berkas- berkas sekolah yang dianggap penting | J37: Terlaksana | K37: 1 Keg
A38: =IF(C38="","",COUNT($C$21:D38)&".") | B38: =IF(C38="","",TEXT(C38&D38,"dddd")) | D38: =IF(C38="","",PROPER(DATA!$E$17)&" "&DATA!$G$17) | E38: 10.00-12.00 | I38: Menyiapkan bahan ajar untuk membuat Program Tahunan Mapel SKI kls 8 semester ganjil TP 2026/2027 | J38: Terlaksana | K38: 1 Keg
A39: =IF(C39="","",COUNT($C$21:D39)&".") | B39: =IF(C39="","",TEXT(C39&D39,"dddd")) | D39: =IF(C39="","",PROPER(DATA!$E$17)&" "&DATA!$G$17) | E39: 12.00-13.00 | I39: Istirahat dan Shalat Dzuhur | J39: Terlaksana | K39: 1 Keg
A40: =IF(C40="","",COUNT($C$21:D40)&".") | B40: =IF(C40="","",TEXT(C40&D40,"dddd")) | D40: =IF(C40="","",PROPER(DATA!$E$17)&" "&DATA!$G$17) | E40: 13.00-15.00 | I40: Melanjutkan kegiatan membuat Program Tahunan Mapel SKI kls 8 | J40: Terlaksana | K40: 1 Keg
A41: =IF(C41="","",COUNT($C$21:D41)&".") -> 7. | B41: =IF(C41="","",TEXT(C41&D41,"dddd")) -> Rabu | C41: 8 | D41: =IF(C41="","",PROPER(DATA!$E$17)&" "&DATA!$G$17) -> Juli 2026 | E41: 07.30-09.00 | I41: Membuat Program Semester Mapel SKI kls 8 | J41: Terlaksana | K41: 1 Keg
A42: =IF(C42="","",COUNT($C$21:D42)&".") | B42: =IF(C42="","",TEXT(C42&D42,"dddd")) | D42: =IF(C42="","",PROPER(DATA!$E$17)&" "&DATA!$G$17) | E42: 09.00-12.00 | I42: Melanjutkan membuat program semester ganjil mapel SKI kls 8 | J42: Terlaksana | K42: 1 Keg
A43: =IF(C43="","",COUNT($C$21:D43)&".") | B43: =IF(C43="","",TEXT(C43&D43,"dddd")) | D43: =IF(C43="","",PROPER(DATA!$E$17)&" "&DATA!$G$17) | E43: 12.00-13.00 | I43: Istirahat dan Shalat Dzuhur | J43: Terlaksana | K43: 1 Keg
A44: =IF(C44="","",COUNT($C$21:D44)&".") | B44: =IF(C44="","",TEXT(C44&D44,"dddd")) | D44: =IF(C44="","",PROPER(DATA!$E$17)&" "&DATA!$G$17) | E44: 13.00-15.00 | I44: Melanjutkan kegiatan membuat program pembelajaran semester ganjil mapel SKI kls 8 | J44: Terlaksana | K44: 1 Keg
...

Sheet TEST
A1: A | B1: B
B2: =A2 -> 0

Sheet LAPORAN BULANAN
A1: YAYASAN AL – IHSAN AL ISLAMI | U1: aquila alfazza
A2: MTs. AL IHSAN TANAH GROGOT | U2: aquila alfazza
A3: NPSN : 30410000 NSM : 12.12.64.01.0002 | U3: aquila alfazza
A4: Alamat : Jl. Senaken Ds. Senaken RT. IV Tanah Grogot Kab. Paser - Kalimantan Timur 76211 | U4: aquila alfazza
A5: Telp. 0543-5236320 e-mail: mtsalihsan__senaken@yahoo.com | U5: aquila alfazza
U6: aquila alfazza
U7: aquila alfazza
A8: ="LAPORAN BULANAN"&" "&"TAHUN AJARAN : "&DATA!E15 -> LAPORAN BULANAN TAHUN AJARAN : 2026/2027 | U8: aquila alfazza
A9: =JURNAL_LKH!A9 -> BULAN : JULI 2026 | U9: aquila alfazza
A10: IDENTITAS GURU | I10: IDENTITAS MADRASAH | U10: aquila alfazza
A11: =JURNAL_LKH!A11 -> Nama Guru : Nurlailatul Hasanah, S.Ag | I11: =JURNAL_LKH!I11 -> Nama Madrasah : MTs. AL IHSAN TANAH GROGOT | U11: aquila alfazza
A12: =JURNAL_LKH!A12 -> NIP : 197311272005012002 | I12: =JURNAL_LKH!I12 -> Alamat Madrasah : Jl. Cendrawasih RT. 04 Desa Senaken Tanah Grogot | U12: aquila alfazza
A13: =JURNAL_LKH!A13 -> No Sertifikasi : 2111423801163 | I13: =JURNAL_LKH!I13 -> Jumlah Ruang Kelas : 6 (Enam) | U13: aquila alfazza
A14: =JURNAL_LKH!A14 -> Pangkat/Gol Ruang : Guru madya pembina tingkat I, golongan IV/b | I14: =JURNAL_LKH!I14 -> Status Madrasah : Terakreditasi A | U14: aquila alfazza
A15: =JURNAL_LKH!A15 -> Pendidikan : S.1 Tarbiyah | I15: =JURNAL_LKH!I15 -> Internet : Ada | U15: aquila alfazza
A16: =JURNAL_LKH!A16 -> Status Guru : Sejarah Kebudayaan Islam (SKI) dan Akidah Akhlak | U16: aquila alfazza
A17: LAPORAN KEGIATAN GURU DAN DATA MURID | U17: aquila alfazza
A18: WAJIB MENGAJAR TIAP MINGGU | D18: JUMLAH MURID | H18: PRESENTASI GURU | N18: PRESENTASI SISWA | T18: KET | U18: aquila alfazza
H19: Sakit | J19: Izin | L19: Alpa | N19: Sakit | P19: Izin | R19: Alpa | U19: aquila alfazza
A20: HARI | B20: JUMLAH JAM | C20: JAM KE- | D20: KELAS | E20: L | F20: P | G20: JUMLAH | H20: JML | I20: % | J20: JML | K20: % | L20: JML | M20: % | N20: JML | O20: % | P20: JML | Q20: % | R20: JML | S20: % | U20: aquila alfazza | V20: Pengali
A21: SENIN | B21: 2 | C21: 3-4 | D21: VII A | E21: =VLOOKUP(D21,$E$67:$G$82,2,FALSE) -> 24 | F21: =VLOOKUP(D21,$E$67:$G$82,3,FALSE) -> 0 | G21: =SUM(E21:F21) -> 24 | H21: 0 | I21: =IF(H21=0,0%,H21/V21) -> 0 | J21: 0 | K21: =IF(J21=0,0%,J21/V21) -> 0 | L21: 0 | M21: =IF(L21=0,0%,L21/V21) -> 0 | N21: =SUMIF(proses!$C$21:$C$188,'LAPORAN BULANAN'!X21,JURNAL_LKH!$L$21:$L$188) -> 0 | O21: =N21/(G21*V21) -> 0 | P21: =SUMIF(proses!$C$21:$C$188,'LAPORAN BULANAN'!X21,JURNAL_LKH!$M$21:$M$188) -> 0 | Q21: =P21/(G21*V21) -> 0 | R21: =SUMIF(proses!$C$21:$C$188,'LAPORAN BULANAN'!X21,JURNAL_LKH!$N$21:$N$188) -> 0 | S21: =R21/(G21*V21) -> 0 | U21: aquila alfazza | V21: =DATA!G47 -> 3 | X21: =$A$21&C21&D21 -> SENIN3-4VII A | AA21: w
B22: 2 | C22: 7-8 | D22: VIII B | E22: =VLOOKUP(D22,$E$67:$G$82,2,FALSE) -> 12 | F22: =VLOOKUP(D22,$E$67:$G$82,3,FALSE) -> 11 | G22: =SUM(E22:F22) -> 23 | H22: 0 | I22: =IF(H22=0,0%,H22/V22) -> 0 | J22: 0 | K22: =IF(J22=0,0%,J22/V22) -> 0 | L22: 0 | M22: =IF(L22=0,0%,L22/V22) -> 0 | N22: =SUMIF(proses!$C$21:$C$188,'LAPORAN BULANAN'!X22,JURNAL_LKH!$L$21:$L$188) -> 0 | O22: =N22/(G22*V22) -> 0 | P22: =SUMIF(proses!$C$21:$C$188,'LAPORAN BULANAN'!X22,JURNAL_LKH!$M$21:$M$188) -> 0 | Q22: =P22/(G22*V22) -> 0 | R22: =SUMIF(proses!$C$21:$C$188,'LAPORAN BULANAN'!X22,JURNAL_LKH!$N$21:$N$188) -> 0 | S22: =R22/(G22*V22) -> 0 | U22: aquila alfazza | V22: =DATA!G47 -> 3 | X22: =$A$21&C22&D22 -> SENIN7-8VIII B | AA22: w
E23: =VLOOKUP(D23,$E$67:$G$82,2,FALSE) -> 0 | F23: =VLOOKUP(D23,$E$67:$G$82,3,FALSE) -> 0 | G23: =SUM(E23:F23) -> 0 | H23: 0 | I23: =IF(H23=0,0%,H23/V23) -> 0 | J23: 0 | K23: =IF(J23=0,0%,J23/V23) -> 0 | L23: 0 | M23: =IF(L23=0,0%,L23/V23) -> 0 | N23: =SUMIF(proses!$C$21:$C$188,'LAPORAN BULANAN'!X23,JURNAL_LKH!$L$21:$L$188) -> 0 | O23: =N23/(G23*V23) -> #DIV/0! | P23: =SUMIF(proses!$C$21:$C$188,'LAPORAN BULANAN'!X23,JURNAL_LKH!$M$21:$M$188) -> 0 | Q23: =P23/(G23*V23) -> #DIV/0! | R23: =SUMIF(proses!$C$21:$C$188,'LAPORAN BULANAN'!X23,JURNAL_LKH!$N$21:$N$188) -> 0 | S23: =R23/(G23*V23) -> #DIV/0! | U23: aquila alfazza | V23: =DATA!G47 -> 3 | X23: =$A$21&C23&D23 -> SENIN
E24: =VLOOKUP(D24,$E$67:$G$82,2,FALSE) -> 0 | F24: =VLOOKUP(D24,$E$67:$G$82,3,FALSE) -> 0 | G24: =SUM(E24:F24) -> 0 | H24: 0 | I24: =IF(H24=0,0%,H24/V24) -> 0 | J24: 0 | K24: =IF(J24=0,0%,J24/V24) -> 0 | L24: 0 | M24: =IF(L24=0,0%,L24/V24) -> 0 | N24: =SUMIF(proses!$C$21:$C$188,'LAPORAN BULANAN'!X24,JURNAL_LKH!$L$21:$L$188) -> 0 | O24: =N24/(G24*V24) -> #DIV/0! | P24: =SUMIF(proses!$C$21:$C$188,'LAPORAN BULANAN'!X24,JURNAL_LKH!$M$21:$M$188) -> 0 | Q24: =P24/(G24*V24) -> #DIV/0! | R24: =SUMIF(proses!$C$21:$C$188,'LAPORAN BULANAN'!X24,JURNAL_LKH!$N$21:$N$188) -> 0 | S24: =R24/(G24*V24) -> #DIV/0! | U24: aquila alfazza | V24: =DATA!G47 -> 3 | X24: =$A$21&C24&D24 -> SENIN
A25: SELASA | B25: 2 | C25: 1-2 | D25: VII B | E25: =VLOOKUP(D25,$E$67:$G$82,2,FALSE) -> 0 | F25: =VLOOKUP(D25,$E$67:$G$82,3,FALSE) -> 20 | G25: =SUM(E25:F25) -> 20 | H25: 0 | I25: =IF(H25=0,0%,H25/V25) -> 0 | J25: 0 | K25: =IF(J25=0,0%,J25/V25) -> 0 | L25: 0 | M25: =IF(L25=0,0%,L25/V25) -> 0 | N25: =SUMIF(proses!$C$21:$C$188,'LAPORAN BULANAN'!X25,JURNAL_LKH!$L$21:$L$188) -> 0 | O25: =N25/(G25*V25) -> 0 | P25: =SUMIF(proses!$C$21:$C$188,'LAPORAN BULANAN'!X25,JURNAL_LKH!$M$21:$M$188) -> 0 | Q25: =P25/(G25*V25) -> 0 | R25: =SUMIF(proses!$C$21:$C$188,'LAPORAN BULANAN'!X25,JURNAL_LKH!$N$21:$N$188) -> 0 | S25: =R25/(G25*V25) -> 0 | U25: aquila alfazza | V25: =DATA!H47 -> 3 | X25: =$A$25&C25&D25 -> SELASA1-2VII B | AA25: w
B26: 2 | C26: 5-6 | D26: IX C | E26: =VLOOKUP(D26,$E$67:$G$82,2,FALSE) -> 0 | F26: =VLOOKUP(D26,$E$67:$G$82,3,FALSE) -> 0 | G26: =SUM(E26:F26) -> 0 | H26: 0 | I26: =IF(H26=0,0%,H26/V26) -> 0 | J26: 0 | K26: =IF(J26=0,0%,J26/V26) -> 0 | L26: 0 | M26: =IF(L26=0,0%,L26/V26) -> 0 | N26: =SUMIF(proses!$C$21:$C$188,'LAPORAN BULANAN'!X26,JURNAL_LKH!$L$21:$L$188) -> 0 | O26: =N26/(G26*V26) -> #DIV/0! | P26: =SUMIF(proses!$C$21:$C$188,'LAPORAN BULANAN'!X26,JURNAL_LKH!$M$21:$M$188) -> 0 | Q26: =P26/(G26*V26) -> #DIV/0! | R26: =SUMIF(proses!$C$21:$C$188,'LAPORAN BULANAN'!X26,JURNAL_LKH!$N$21:$N$188) -> 0 | S26: =R26/(G26*V26) -> #DIV/0! | U26: aquila alfazza | V26: =DATA!H47 -> 3 | X26: =$A$25&C26&D26 -> SELASA5-6IX C | AA26: w
B27: 2 | C27: 7-8 | D27: IX A | E27: =VLOOKUP(D27,$E$67:$G$82,2,FALSE) -> 23 | F27: =VLOOKUP(D27,$E$67:$G$82,3,FALSE) -> 0 | G27: =SUM(E27:F27) -> 23 | H27: 0 | I27: =IF(H27=0,0%,H27/V27) -> 0 | J27: 0 | K27: =IF(J27=0,0%,J27/V27) -> 0 | L27: 0 | M27: =IF(L27=0,0%,L27/V27) -> 0 | N27: =SUMIF(proses!$C$21:$C$188,'LAPORAN BULANAN'!X27,JURNAL_LKH!$L$21:$L$188) -> 0 | O27: =N27/(G27*V27) -> 0 | P27: =SUMIF(proses!$C$21:$C$188,'LAPORAN BULANAN'!X27,JURNAL_LKH!$M$21:$M$188) -> 0 | Q27: =P27/(G27*V27) -> 0 | R27: =SUMIF(proses!$C$21:$C$188,'LAPORAN BULANAN'!X27,JURNAL_LKH!$N$21:$N$188) -> 0 | S27: =R27/(G27*V27) -> 0 | U27: aquila alfazza | V27: =DATA!H47 -> 3 | X27: =$A$25&C27&D27 -> SELASA7-8IX A | AA27: w
E28: =VLOOKUP(D28,$E$67:$G$82,2,FALSE) -> 0 | F28: =VLOOKUP(D28,$E$67:$G$82,3,FALSE) -> 0 | G28: =SUM(E28:F28) -> 0 | H28: 0 | I28: =IF(H28=0,0%,H28/V28) -> 0 | J28: 0 | K28: =IF(J28=0,0%,J28/V28) -> 0 | L28: 0 | M28: =IF(L28=0,0%,L28/V28) -> 0 | N28: =SUMIF(proses!$C$21:$C$188,'LAPORAN BULANAN'!X28,JURNAL_LKH!$L$21:$L$188) -> 0 | O28: =N28/(G28*V28) -> #DIV/0! | P28: =SUMIF(proses!$C$21:$C$188,'LAPORAN BULANAN'!X28,JURNAL_LKH!$M$21:$M$188) -> 0 | Q28: =P28/(G28*V28) -> #DIV/0! | R28: =SUMIF(proses!$C$21:$C$188,'LAPORAN BULANAN'!X28,JURNAL_LKH!$N$21:$N$188) -> 0 | S28: =R28/(G28*V28) -> #DIV/0! | U28: aquila alfazza | V28: =DATA!H47 -> 3 | X28: =$A$25&C28&D28 -> SELASA | AA28: w
A29: RABU | E29: =VLOOKUP(D29,$E$67:$G$82,2,FALSE) -> 0 | F29: =VLOOKUP(D29,$E$67:$G$82,3,FALSE) -> 0 | G29: =SUM(E29:F29) -> 0 | H29: 0 | I29: =IF(H29=0,0%,H29/V29) -> 0 | J29: 0 | K29: =IF(J29=0,0%,J29/V29) -> 0 | L29: 0 | M29: =IF(L29=0,0%,L29/V29) -> 0 | N29: =SUMIF(proses!$C$21:$C$188,'LAPORAN BULANAN'!X29,JURNAL_LKH!$L$21:$L$188) -> 0 | O29: =N29/(G29*V29) -> #DIV/0! | P29: =SUMIF(proses!$C$21:$C$188,'LAPORAN BULANAN'!X29,JURNAL_LKH!$M$21:$M$188) -> 0 | Q29: =P29/(G29*V29) -> #DIV/0! | R29: =SUMIF(proses!$C$21:$C$188,'LAPORAN BULANAN'!X29,JURNAL_LKH!$N$21:$N$188) -> 0 | S29: =R29/(G29*V29) -> #DIV/0! | U29: aquila alfazza | V29: =DATA!I47 -> 3 | X29: =$A$29&C29&D29 -> RABU | AA29: w
E30: =VLOOKUP(D30,$E$67:$G$82,2,FALSE) -> 0 | F30: =VLOOKUP(D30,$E$67:$G$82,3,FALSE) -> 0 | G30: =SUM(E30:F30) -> 0 | H30: 0 | I30: =IF(H30=0,0%,H30/V30) -> 0 | J30: 0 | K30: =IF(J30=0,0%,J30/V30) -> 0 | L30: 0 | M30: =IF(L30=0,0%,L30/V30) -> 0 | N30: =SUMIF(proses!$C$21:$C$188,'LAPORAN BULANAN'!X30,JURNAL_LKH!$L$21:$L$188) -> 0 | O30: =N30/(G30*V30) -> #DIV/0! | P30: =SUMIF(proses!$C$21:$C$188,'LAPORAN BULANAN'!X30,JURNAL_LKH!$M$21:$M$188) -> 0 | Q30: =P30/(G30*V30) -> #DIV/0! | R30: =SUMIF(proses!$C$21:$C$188,'LAPORAN BULANAN'!X30,JURNAL_LKH!$N$21:$N$188) -> 0 | S30: =R30/(G30*V30) -> #DIV/0! | U30: aquila alfazza | V30: =DATA!I47 -> 3 | X30: =$A$29&C30&D30 -> RABU
D31: VIII A | E31: =VLOOKUP(D31,$E$67:$G$82,2,FALSE) -> 22 | F31: =VLOOKUP(D31,$E$67:$G$82,3,FALSE) -> 0 | G31: =SUM(E31:F31) -> 22 | H31: 0 | I31: =IF(H31=0,0%,H31/V31) -> 0 | J31: 0 | K31: =IF(J31=0,0%,J31/V31) -> 0 | L31: 0 | M31: =IF(L31=0,0%,L31/V31) -> 0 | N31: =SUMIF(proses!$C$21:$C$188,'LAPORAN BULANAN'!X31,JURNAL_LKH!$L$21:$L$188) -> 0 | O31: =N31/(G31*V31) -> 0 | P31: =SUMIF(proses!$C$21:$C$188,'LAPORAN BULANAN'!X31,JURNAL_LKH!$M$21:$M$188) -> 0 | Q31: =P31/(G31*V31) -> 0 | R31: =SUMIF(proses!$C$21:$C$188,'LAPORAN BULANAN'!X31,JURNAL_LKH!$N$21:$N$188) -> 0 | S31: =R31/(G31*V31) -> 0 | U31: aquila alfazza | V31: =DATA!I47 -> 3 | X31: =$A$29&C31&D31 -> RABUVIII A
E32: =VLOOKUP(D32,$E$67:$G$82,2,FALSE) -> 0 | F32: =VLOOKUP(D32,$E$67:$G$82,3,FALSE) -> 0 | G32: =SUM(E32:F32) -> 0 | H32: 0 | I32: =IF(H32=0,0%,H32/V32) -> 0 | J32: 0 | K32: =IF(J32=0,0%,J32/V32) -> 0 | L32: 0 | M32: =IF(L32=0,0%,L32/V32) -> 0 | N32: =SUMIF(proses!$C$21:$C$188,'LAPORAN BULANAN'!X32,JURNAL_LKH!$L$21:$L$188) -> 0 | O32: =N32/(G32*V32) -> #DIV/0! | P32: =SUMIF(proses!$C$21:$C$188,'LAPORAN BULANAN'!X32,JURNAL_LKH!$M$21:$M$188) -> 0 | Q32: =P32/(G32*V32) -> #DIV/0! | R32: =SUMIF(proses!$C$21:$C$188,'LAPORAN BULANAN'!X32,JURNAL_LKH!$N$21:$N$188) -> 0 | S32: =R32/(G32*V32) -> #DIV/0! | U32: aquila alfazza | V32: =DATA!I47 -> 3 | X32: =$A$29&C32&D32 -> RABU
A33: KAMIS | B33: 2 | C33: 1-2 | D33: VIII A | E33: =VLOOKUP(D33,$E$67:$G$82,2,FALSE) -> 22 | F33: =VLOOKUP(D33,$E$67:$G$82,3,FALSE) -> 0 | G33: =SUM(E33:F33) -> 22 | H33: 0 | I33: =IF(H33=0,0%,H33/V33) -> 0 | J33: 0 | K33: =IF(J33=0,0%,J33/V33) -> 0 | L33: 0 | M33: =IF(L33=0,0%,L33/V33) -> 0 | N33: =SUMIF(proses!$C$21:$C$188,'LAPORAN BULANAN'!X33,JURNAL_LKH!$L$21:$L$188) -> 0 | O33: =N33/(G33*V33) -> 0 | P33: =SUMIF(proses!$C$21:$C$188,'LAPORAN BULANAN'!X33,JURNAL_LKH!$M$21:$M$188) -> 0 | Q33: =P33/(G33*V33) -> 0 | R33: =SUMIF(proses!$C$21:$C$188,'LAPORAN BULANAN'!X33,JURNAL_LKH!$N$21:$N$188) -> 0 | S33: =R33/(G33*V33) -> 0 | U33: aquila alfazza | V33: =DATA!J47 -> 3 | X33: =$A$33&C33&D33 -> KAMIS1-2VIII A | AA33: w
B34: 2 | C34: 3-4 | D34: IX B | E34: =VLOOKUP(D34,$E$67:$G$82,2,FALSE) -> 0 | F34: =VLOOKUP(D34,$E$67:$G$82,3,FALSE) -> 31 | G34: =SUM(E34:F34) -> 31 | H34: 0 | I34: =IF(H34=0,0%,H34/V34) -> 0 | J34: 0 | K34: =IF(J34=0,0%,J34/V34) -> 0 | L34: 0 | M34: =IF(L34=0,0%,L34/V34) -> 0 | N34: =SUMIF(proses!$C$21:$C$188,'LAPORAN BULANAN'!X34,JURNAL_LKH!$L$21:$L$188) -> 0 | O34: =N34/(G34*V34) -> 0 | P34: =SUMIF(proses!$C$21:$C$188,'LAPORAN BULANAN'!X34,JURNAL_LKH!$M$21:$M$188) -> 0 | Q34: =P34/(G34*V34) -> 0 | R34: =SUMIF(proses!$C$21:$C$188,'LAPORAN BULANAN'!X34,JURNAL_LKH!$N$21:$N$188) -> 0 | S34: =R34/(G34*V34) -> 0 | U34: aquila alfazza | V34: =DATA!J47 -> 3 | X34: =$A$33&C34&D34 -> KAMIS3-4IX B | AA34: w
B35: 2 | C35: 7-8 | D35: IX C | E35: =VLOOKUP(D35,$E$67:$G$82,2,FALSE) -> 0 | F35: =VLOOKUP(D35,$E$67:$G$82,3,FALSE) -> 0 | G35: =SUM(E35:F35) -> 0 | H35: 0 | I35: =IF(H35=0,0%,H35/V35) -> 0 | J35: 0 | K35: =IF(J35=0,0%,J35/V35) -> 0 | L35: 0 | M35: =IF(L35=0,0%,L35/V35) -> 0 | N35: =SUMIF(proses!$C$21:$C$188,'LAPORAN BULANAN'!X35,JURNAL_LKH!$L$21:$L$188) -> 0 | O35: =N35/(G35*V35) -> #DIV/0! | P35: =SUMIF(proses!$C$21:$C$188,'LAPORAN BULANAN'!X35,JURNAL_LKH!$M$21:$M$188) -> 0 | Q35: =P35/(G35*V35) -> #DIV/0! | R35: =SUMIF(proses!$C$21:$C$188,'LAPORAN BULANAN'!X35,JURNAL_LKH!$N$21:$N$188) -> 0 | S35: =R35/(G35*V35) -> #DIV/0! | U35: aquila alfazza | V35: =DATA!J47 -> 3 | X35: =$A$33&C35&D35 -> KAMIS7-8IX C | AA35: w
E36: =VLOOKUP(D36,$E$67:$G$82,2,FALSE) -> 0 | F36: =VLOOKUP(D36,$E$67:$G$82,3,FALSE) -> 0 | G36: =SUM(E36:F36) -> 0 | H36: 0 | I36: =IF(H36=0,0%,H36/V36) -> 0 | J36: 0 | K36: =IF(J36=0,0%,J36/V36) -> 0 | L36: 0 | M36: =IF(L36=0,0%,L36/V36) -> 0 | N36: =SUMIF(proses!$C$21:$C$188,'LAPORAN BULANAN'!X36,JURNAL_LKH!$L$21:$L$188) -> 0 | O36: =N36/(G36*V36) -> #DIV/0! | P36: =SUMIF(proses!$C$21:$C$188,'LAPORAN BULANAN'!X36,JURNAL_LKH!$M$21:$M$188) -> 0 | Q36: =P36/(G36*V36) -> #DIV/0! | R36: =SUMIF(proses!$C$21:$C$188,'LAPORAN BULANAN'!X36,JURNAL_LKH!$N$21:$N$188) -> 0 | S36: =R36/(G36*V36) -> #DIV/0! | U36: aquila alfazza | V36: =DATA!J47 -> 3 | X36: =$A$33&C36&D36 -> KAMIS | AA36: w
A37: JUMAT | E37: =VLOOKUP(D37,$E$67:$G$82,2,FALSE) -> 0 | F37: =VLOOKUP(D37,$E$67:$G$82,3,FALSE) -> 0 | G37: =SUM(E37:F37) -> 0 | H37: 0 | I37: =IF(H37=0,0%,H37/V37) -> 0 | J37: 0 | K37: =IF(J37=0,0%,J37/V37) -> 0 | L37: 0 | M37: =IF(L37=0,0%,L37/V37) -> 0 | N37: =SUMIF(proses!$C$21:$C$188,'LAPORAN BULANAN'!X37,JURNAL_LKH!$L$21:$L$188) -> 0 | O37: =N37/(G37*V37) -> #DIV/0! | P37: =SUMIF(proses!$C$21:$C$188,'LAPORAN BULANAN'!X37,JURNAL_LKH!$M$21:$M$188) -> 0 | Q37: =P37/(G37*V37) -> #DIV/0! | R37: =SUMIF(proses!$C$21:$C$188,'LAPORAN BULANAN'!X37,JURNAL_LKH!$N$21:$N$188) -> 0 | S37: =R37/(G37*V37) -> #DIV/0! | U37: aquila alfazza | V37: =DATA!K47 -> 3 | X37: =$A$37&C37&D37 -> JUMAT | AA37: w
E38: =VLOOKUP(D38,$E$67:$G$82,2,FALSE) -> 0 | F38: =VLOOKUP(D38,$E$67:$G$82,3,FALSE) -> 0 | G38: =SUM(E38:F38) -> 0 | H38: 0 | I38: =IF(H38=0,0%,H38/V38) -> 0 | J38: 0 | K38: =IF(J38=0,0%,J38/V38) -> 0 | L38: 0 | M38: =IF(L38=0,0%,L38/V38) -> 0 | N38: =SUMIF(proses!$C$21:$C$188,'LAPORAN BULANAN'!X38,JURNAL_LKH!$L$21:$L$188) -> 0 | O38: =N38/(G38*V38) -> #DIV/0! | P38: =SUMIF(proses!$C$21:$C$188,'LAPORAN BULANAN'!X38,JURNAL_LKH!$M$21:$M$188) -> 0 | Q38: =P38/(G38*V38) -> #DIV/0! | R38: =SUMIF(proses!$C$21:$C$188,'LAPORAN BULANAN'!X38,JURNAL_LKH!$N$21:$N$188) -> 0 | S38: =R38/(G38*V38) -> #DIV/0! | V38: =DATA!K47 -> 3 | X38: =$A$37&C38&D38 -> JUMAT
E39: =VLOOKUP(D39,$E$67:$G$82,2,FALSE) -> 0 | F39: =VLOOKUP(D39,$E$67:$G$82,3,FALSE) -> 0 | G39: =SUM(E39:F39) -> 0 | H39: 0 | I39: =IF(H39=0,0%,H39/V39) -> 0 | J39: 0 | K39: =IF(J39=0,0%,J39/V39) -> 0 | L39: 0 | M39: =IF(L39=0,0%,L39/V39) -> 0 | N39: =SUMIF(proses!$C$21:$C$188,'LAPORAN BULANAN'!X39,JURNAL_LKH!$L$21:$L$188) -> 0 | O39: =N39/(G39*V39) -> #DIV/0! | P39: =SUMIF(proses!$C$21:$C$188,'LAPORAN BULANAN'!X39,JURNAL_LKH!$M$21:$M$188) -> 0 | Q39: =P39/(G39*V39) -> #DIV/0! | R39: =SUMIF(proses!$C$21:$C$188,'LAPORAN BULANAN'!X39,JURNAL_LKH!$N$21:$N$188) -> 0 | S39: =R39/(G39*V39) -> #DIV/0! | U39: aquila alfazza | V39: =DATA!K47 -> 3 | X39: =$A$37&C39&D39 -> JUMAT
A40: SABTU | B40: 2 | C40: 5-6 | D40: IX B | E40: =VLOOKUP(D40,$E$67:$G$82,2,FALSE) -> 0 | F40: =VLOOKUP(D40,$E$67:$G$82,3,FALSE) -> 31 | G40: =SUM(E40:F40) -> 31 | H40: 0 | I40: =IF(H40=0,0%,H40/V40) -> 0 | J40: 0 | K40: =IF(J40=0,0%,J40/V40) -> 0 | L40: 0 | M40: =IF(L40=0,0%,L40/V40) -> 0 | N40: =SUMIF(proses!$C$21:$C$188,'LAPORAN BULANAN'!X40,JURNAL_LKH!$L$21:$L$188) -> 0 | O40: =N40/(G40*V40) -> 0 | P40: =SUMIF(proses!$C$21:$C$188,'LAPORAN BULANAN'!X40,JURNAL_LKH!$M$21:$M$188) -> 0 | Q40: =P40/(G40*V40) -> 0 | R40: =SUMIF(proses!$C$21:$C$188,'LAPORAN BULANAN'!X40,JURNAL_LKH!$N$21:$N$188) -> 0 | S40: =R40/(G40*V40) -> 0 | U40: aquila alfazza | V40: =DATA!L47 -> 2 | X40: =$A$40&C40&D40 -> SABTU5-6IX B | AA40: w
...

Sheet Sheet1
A1: SENIN | B1: 2 | C1: 4-5 | D1: VIII C
B2: 2 | C2: 6-7 | D2: IX C
A5: SELASA | B5: 2 | C5: 1-2 | D5: VII B
B6: 2 | C6: 3-4 | D6: VIII D
B7: 2 | C7: 5-6 | D7: VII C
B8: 2 | C8: 7-8 | D8: VII A
A9: RABU | B9: 2 | C9: 1-2 | D9: VIII A
A13: KAMIS | B13: 2 | C13: 1-2 | D13: IX E
B14: 2 | C14: 3-4 | D14: IX A
B15: 2 | C15: 5-6 | D15: VIII B
B16: 2 | C16: 7-8 | D16: IX B
A17: JUMAT | B17: 2 | C17: 4-5 | D17: VIII E
A20: SABTU | B20: 2 | C20: 6-7 | D20: IX D
